[2025-11-01T14:16:25.314+0000] {taskinstance.py:1956} INFO - Dependencies all met for dep_context=non-requeueable deps ti=<TaskInstance: silver_transformation_pipeline.dbt_test_linktx scheduled__2025-10-30T00:00:00+00:00 [queued]>
[2025-11-01T14:16:25.327+0000] {taskinstance.py:1956} INFO - Dependencies all met for dep_context=requeueable deps ti=<TaskInstance: silver_transformation_pipeline.dbt_test_linktx scheduled__2025-10-30T00:00:00+00:00 [queued]>
[2025-11-01T14:16:25.328+0000] {taskinstance.py:2170} INFO - Starting attempt 1 of 2
[2025-11-01T14:16:25.343+0000] {taskinstance.py:2191} INFO - Executing <Task(BashOperator): dbt_test_linktx> on 2025-10-30 00:00:00+00:00
[2025-11-01T14:16:25.350+0000] {standard_task_runner.py:60} INFO - Started process 688 to run task
[2025-11-01T14:16:25.353+0000] {standard_task_runner.py:87} INFO - Running: ['***', 'tasks', 'run', 'silver_transformation_pipeline', 'dbt_test_linktx', 'scheduled__2025-10-30T00:00:00+00:00', '--job-id', '21', '--raw', '--subdir', 'DAGS_FOLDER/silver_dag.py', '--cfg-path', '/tmp/tmpzevrrgki']
[2025-11-01T14:16:25.357+0000] {standard_task_runner.py:88} INFO - Job 21: Subtask dbt_test_linktx
[2025-11-01T14:16:25.441+0000] {task_command.py:423} INFO - Running <TaskInstance: silver_transformation_pipeline.dbt_test_linktx scheduled__2025-10-30T00:00:00+00:00 [running]> on host b977057f5fed
[2025-11-01T14:16:25.543+0000] {taskinstance.py:2480} INFO - Exporting env vars: AIRFLOW_CTX_DAG_OWNER='***' AIRFLOW_CTX_DAG_ID='silver_transformation_pipeline' AIRFLOW_CTX_TASK_ID='dbt_test_linktx' AIRFLOW_CTX_EXECUTION_DATE='2025-10-30T00:00:00+00:00' AIRFLOW_CTX_TRY_NUMBER='1' AIRFLOW_CTX_DAG_RUN_ID='scheduled__2025-10-30T00:00:00+00:00'
[2025-11-01T14:16:25.546+0000] {subprocess.py:63} INFO - Tmp dir root location: /tmp
[2025-11-01T14:16:25.548+0000] {subprocess.py:75} INFO - Running command: ['/usr/bin/bash', '-c', 'dbt --no-use-colors test --project-dir /opt/***/dbt_project --profiles-dir /opt/***/dbt_project --select silver_link_transactions']
[2025-11-01T14:16:25.558+0000] {subprocess.py:86} INFO - Output:
[2025-11-01T14:16:27.551+0000] {subprocess.py:93} INFO - 14:16:27  Running with dbt=1.8.6
[2025-11-01T14:16:27.568+0000] {subprocess.py:93} INFO - 14:16:27  Encountered an error:
[2025-11-01T14:16:27.569+0000] {subprocess.py:93} INFO - 'type' object is not subscriptable
[2025-11-01T14:16:27.570+0000] {subprocess.py:93} INFO - 14:16:27  Traceback (most recent call last):
[2025-11-01T14:16:27.571+0000] {subprocess.py:93} INFO -   File "/home/***/.local/lib/python3.8/site-packages/dbt/cli/requires.py", line 138, in wrapper
[2025-11-01T14:16:27.572+0000] {subprocess.py:93} INFO -     result, success = func(*args, **kwargs)
[2025-11-01T14:16:27.572+0000] {subprocess.py:93} INFO -   File "/home/***/.local/lib/python3.8/site-packages/dbt/cli/requires.py", line 101, in wrapper
[2025-11-01T14:16:27.572+0000] {subprocess.py:93} INFO -     return func(*args, **kwargs)
[2025-11-01T14:16:27.573+0000] {subprocess.py:93} INFO -   File "/home/***/.local/lib/python3.8/site-packages/dbt/cli/requires.py", line 215, in wrapper
[2025-11-01T14:16:27.574+0000] {subprocess.py:93} INFO -     profile = load_profile(flags.PROJECT_DIR, flags.VARS, flags.PROFILE, flags.TARGET, threads)
[2025-11-01T14:16:27.574+0000] {subprocess.py:93} INFO -   File "/home/***/.local/lib/python3.8/site-packages/dbt/config/runtime.py", line 71, in load_profile
[2025-11-01T14:16:27.575+0000] {subprocess.py:93} INFO -     profile = Profile.render(
[2025-11-01T14:16:27.575+0000] {subprocess.py:93} INFO -   File "/home/***/.local/lib/python3.8/site-packages/dbt/config/profile.py", line 403, in render
[2025-11-01T14:16:27.576+0000] {subprocess.py:93} INFO -     return cls.from_raw_profiles(
[2025-11-01T14:16:27.577+0000] {subprocess.py:93} INFO -   File "/home/***/.local/lib/python3.8/site-packages/dbt/config/profile.py", line 369, in from_raw_profiles
[2025-11-01T14:16:27.577+0000] {subprocess.py:93} INFO -     return cls.from_raw_profile_info(
[2025-11-01T14:16:27.578+0000] {subprocess.py:93} INFO -   File "/home/***/.local/lib/python3.8/site-packages/dbt/config/profile.py", line 325, in from_raw_profile_info
[2025-11-01T14:16:27.578+0000] {subprocess.py:93} INFO -     credentials: Credentials = cls._credentials_from_profile(
[2025-11-01T14:16:27.579+0000] {subprocess.py:93} INFO -   File "/home/***/.local/lib/python3.8/site-packages/dbt/config/profile.py", line 149, in _credentials_from_profile
[2025-11-01T14:16:27.579+0000] {subprocess.py:93} INFO -     cls = load_plugin(typename)
[2025-11-01T14:16:27.580+0000] {subprocess.py:93} INFO -   File "/home/***/.local/lib/python3.8/site-packages/dbt/adapters/factory.py", line 239, in load_plugin
[2025-11-01T14:16:27.580+0000] {subprocess.py:93} INFO -     return FACTORY.load_plugin(name)
[2025-11-01T14:16:27.581+0000] {subprocess.py:93} INFO -   File "/home/***/.local/lib/python3.8/site-packages/dbt/adapters/factory.py", line 68, in load_plugin
[2025-11-01T14:16:27.581+0000] {subprocess.py:93} INFO -     mod: Any = import_module("." + name, "dbt.adapters")
[2025-11-01T14:16:27.582+0000] {subprocess.py:93} INFO -   File "/usr/local/lib/python3.8/importlib/__init__.py", line 127, in import_module
[2025-11-01T14:16:27.582+0000] {subprocess.py:93} INFO -     return _bootstrap._gcd_import(name[level:], package, level)
[2025-11-01T14:16:27.583+0000] {subprocess.py:93} INFO -   File "<frozen importlib._bootstrap>", line 1014, in _gcd_import
[2025-11-01T14:16:27.583+0000] {subprocess.py:93} INFO -   File "<frozen importlib._bootstrap>", line 991, in _find_and_load
[2025-11-01T14:16:27.583+0000] {subprocess.py:93} INFO -   File "<frozen importlib._bootstrap>", line 975, in _find_and_load_unlocked
[2025-11-01T14:16:27.584+0000] {subprocess.py:93} INFO -   File "<frozen importlib._bootstrap>", line 671, in _load_unlocked
[2025-11-01T14:16:27.584+0000] {subprocess.py:93} INFO -   File "<frozen importlib._bootstrap_external>", line 843, in exec_module
[2025-11-01T14:16:27.585+0000] {subprocess.py:93} INFO -   File "<frozen importlib._bootstrap>", line 219, in _call_with_frames_removed
[2025-11-01T14:16:27.585+0000] {subprocess.py:93} INFO -   File "/home/***/.local/lib/python3.8/site-packages/dbt/adapters/clickhouse/__init__.py", line 4, in <module>
[2025-11-01T14:16:27.586+0000] {subprocess.py:93} INFO -     from dbt.adapters.clickhouse.connections import ClickHouseConnectionManager  # noqa
[2025-11-01T14:16:27.587+0000] {subprocess.py:93} INFO -   File "/home/***/.local/lib/python3.8/site-packages/dbt/adapters/clickhouse/connections.py", line 10, in <module>
[2025-11-01T14:16:27.587+0000] {subprocess.py:93} INFO -     from dbt.adapters.clickhouse.dbclient import ChRetryableException, get_db_client
[2025-11-01T14:16:27.588+0000] {subprocess.py:93} INFO -   File "/home/***/.local/lib/python3.8/site-packages/dbt/adapters/clickhouse/dbclient.py", line 9, in <module>
[2025-11-01T14:16:27.588+0000] {subprocess.py:93} INFO -     from dbt.adapters.clickhouse.credentials import ClickHouseCredentials
[2025-11-01T14:16:27.589+0000] {subprocess.py:93} INFO -   File "/home/***/.local/lib/python3.8/site-packages/dbt/adapters/clickhouse/credentials.py", line 9, in <module>
[2025-11-01T14:16:27.589+0000] {subprocess.py:93} INFO -     class ClickHouseCredentials(Credentials):
[2025-11-01T14:16:27.590+0000] {subprocess.py:93} INFO -   File "/home/***/.local/lib/python3.8/site-packages/dbt/adapters/clickhouse/credentials.py", line 38, in ClickHouseCredentials
[2025-11-01T14:16:27.590+0000] {subprocess.py:93} INFO -     tcp_keepalive: Union[bool, tuple[int, int, int], list[int]] = False
[2025-11-01T14:16:27.591+0000] {subprocess.py:93} INFO - TypeError: 'type' object is not subscriptable
[2025-11-01T14:16:27.591+0000] {subprocess.py:93} INFO - 
[2025-11-01T14:16:28.491+0000] {subprocess.py:97} INFO - Command exited with return code 2
[2025-11-01T14:16:28.507+0000] {taskinstance.py:2698} ERROR - Task failed with exception
Traceback (most recent call last):
  File "/home/airflow/.local/lib/python3.8/site-packages/airflow/models/taskinstance.py", line 433, in _execute_task
    result = execute_callable(context=context, **execute_callable_kwargs)
  File "/home/airflow/.local/lib/python3.8/site-packages/airflow/operators/bash.py", line 212, in execute
    raise AirflowException(
airflow.exceptions.AirflowException: Bash command failed. The command returned a non-zero exit code 2.
[2025-11-01T14:16:28.512+0000] {taskinstance.py:1138} INFO - Marking task as UP_FOR_RETRY. dag_id=silver_transformation_pipeline, task_id=dbt_test_linktx, execution_date=20251030T000000, start_date=20251101T141625, end_date=20251101T141628
[2025-11-01T14:16:28.527+0000] {standard_task_runner.py:107} ERROR - Failed to execute job 21 for task dbt_test_linktx (Bash command failed. The command returned a non-zero exit code 2.; 688)
[2025-11-01T14:16:28.539+0000] {local_task_job_runner.py:234} INFO - Task exited with return code 1
[2025-11-01T14:16:28.558+0000] {taskinstance.py:3280} INFO - 0 downstream tasks scheduled from follow-on schedule check
[2025-11-01T14:26:32.448+0000] {taskinstance.py:1956} INFO - Dependencies all met for dep_context=non-requeueable deps ti=<TaskInstance: silver_transformation_pipeline.dbt_test_linktx scheduled__2025-10-30T00:00:00+00:00 [queued]>
[2025-11-01T14:26:32.460+0000] {taskinstance.py:1956} INFO - Dependencies all met for dep_context=requeueable deps ti=<TaskInstance: silver_transformation_pipeline.dbt_test_linktx scheduled__2025-10-30T00:00:00+00:00 [queued]>
[2025-11-01T14:26:32.461+0000] {taskinstance.py:2170} INFO - Starting attempt 1 of 2
[2025-11-01T14:26:32.477+0000] {taskinstance.py:2191} INFO - Executing <Task(BashOperator): dbt_test_linktx> on 2025-10-30 00:00:00+00:00
[2025-11-01T14:26:32.482+0000] {standard_task_runner.py:60} INFO - Started process 649 to run task
[2025-11-01T14:26:32.487+0000] {standard_task_runner.py:87} INFO - Running: ['***', 'tasks', 'run', 'silver_transformation_pipeline', 'dbt_test_linktx', 'scheduled__2025-10-30T00:00:00+00:00', '--job-id', '20', '--raw', '--subdir', 'DAGS_FOLDER/silver_dag.py', '--cfg-path', '/tmp/tmpxqq9v3xf']
[2025-11-01T14:26:32.490+0000] {standard_task_runner.py:88} INFO - Job 20: Subtask dbt_test_linktx
[2025-11-01T14:26:32.568+0000] {task_command.py:423} INFO - Running <TaskInstance: silver_transformation_pipeline.dbt_test_linktx scheduled__2025-10-30T00:00:00+00:00 [running]> on host 8c60c1c29b68
[2025-11-01T14:26:32.662+0000] {taskinstance.py:2480} INFO - Exporting env vars: AIRFLOW_CTX_DAG_OWNER='***' AIRFLOW_CTX_DAG_ID='silver_transformation_pipeline' AIRFLOW_CTX_TASK_ID='dbt_test_linktx' AIRFLOW_CTX_EXECUTION_DATE='2025-10-30T00:00:00+00:00' AIRFLOW_CTX_TRY_NUMBER='1' AIRFLOW_CTX_DAG_RUN_ID='scheduled__2025-10-30T00:00:00+00:00'
[2025-11-01T14:26:32.664+0000] {subprocess.py:63} INFO - Tmp dir root location: /tmp
[2025-11-01T14:26:32.665+0000] {subprocess.py:75} INFO - Running command: ['/usr/bin/bash', '-c', 'dbt --no-use-colors test --project-dir /opt/***/dbt_project --profiles-dir /opt/***/dbt_project --select silver_link_transactions']
[2025-11-01T14:26:32.674+0000] {subprocess.py:86} INFO - Output:
[2025-11-01T14:26:34.557+0000] {subprocess.py:93} INFO - 14:26:34  Running with dbt=1.8.6
[2025-11-01T14:26:34.578+0000] {subprocess.py:93} INFO - 14:26:34  Encountered an error:
[2025-11-01T14:26:34.578+0000] {subprocess.py:93} INFO - 'type' object is not subscriptable
[2025-11-01T14:26:34.580+0000] {subprocess.py:93} INFO - 14:26:34  Traceback (most recent call last):
[2025-11-01T14:26:34.581+0000] {subprocess.py:93} INFO -   File "/home/***/.local/lib/python3.8/site-packages/dbt/cli/requires.py", line 138, in wrapper
[2025-11-01T14:26:34.581+0000] {subprocess.py:93} INFO -     result, success = func(*args, **kwargs)
[2025-11-01T14:26:34.582+0000] {subprocess.py:93} INFO -   File "/home/***/.local/lib/python3.8/site-packages/dbt/cli/requires.py", line 101, in wrapper
[2025-11-01T14:26:34.583+0000] {subprocess.py:93} INFO -     return func(*args, **kwargs)
[2025-11-01T14:26:34.584+0000] {subprocess.py:93} INFO -   File "/home/***/.local/lib/python3.8/site-packages/dbt/cli/requires.py", line 215, in wrapper
[2025-11-01T14:26:34.584+0000] {subprocess.py:93} INFO -     profile = load_profile(flags.PROJECT_DIR, flags.VARS, flags.PROFILE, flags.TARGET, threads)
[2025-11-01T14:26:34.585+0000] {subprocess.py:93} INFO -   File "/home/***/.local/lib/python3.8/site-packages/dbt/config/runtime.py", line 71, in load_profile
[2025-11-01T14:26:34.585+0000] {subprocess.py:93} INFO -     profile = Profile.render(
[2025-11-01T14:26:34.586+0000] {subprocess.py:93} INFO -   File "/home/***/.local/lib/python3.8/site-packages/dbt/config/profile.py", line 403, in render
[2025-11-01T14:26:34.586+0000] {subprocess.py:93} INFO -     return cls.from_raw_profiles(
[2025-11-01T14:26:34.586+0000] {subprocess.py:93} INFO -   File "/home/***/.local/lib/python3.8/site-packages/dbt/config/profile.py", line 369, in from_raw_profiles
[2025-11-01T14:26:34.587+0000] {subprocess.py:93} INFO -     return cls.from_raw_profile_info(
[2025-11-01T14:26:34.587+0000] {subprocess.py:93} INFO -   File "/home/***/.local/lib/python3.8/site-packages/dbt/config/profile.py", line 325, in from_raw_profile_info
[2025-11-01T14:26:34.587+0000] {subprocess.py:93} INFO -     credentials: Credentials = cls._credentials_from_profile(
[2025-11-01T14:26:34.588+0000] {subprocess.py:93} INFO -   File "/home/***/.local/lib/python3.8/site-packages/dbt/config/profile.py", line 149, in _credentials_from_profile
[2025-11-01T14:26:34.588+0000] {subprocess.py:93} INFO -     cls = load_plugin(typename)
[2025-11-01T14:26:34.590+0000] {subprocess.py:93} INFO -   File "/home/***/.local/lib/python3.8/site-packages/dbt/adapters/factory.py", line 239, in load_plugin
[2025-11-01T14:26:34.594+0000] {subprocess.py:93} INFO -     return FACTORY.load_plugin(name)
[2025-11-01T14:26:34.594+0000] {subprocess.py:93} INFO -   File "/home/***/.local/lib/python3.8/site-packages/dbt/adapters/factory.py", line 68, in load_plugin
[2025-11-01T14:26:34.595+0000] {subprocess.py:93} INFO -     mod: Any = import_module("." + name, "dbt.adapters")
[2025-11-01T14:26:34.595+0000] {subprocess.py:93} INFO -   File "/usr/local/lib/python3.8/importlib/__init__.py", line 127, in import_module
[2025-11-01T14:26:34.596+0000] {subprocess.py:93} INFO -     return _bootstrap._gcd_import(name[level:], package, level)
[2025-11-01T14:26:34.596+0000] {subprocess.py:93} INFO -   File "<frozen importlib._bootstrap>", line 1014, in _gcd_import
[2025-11-01T14:26:34.597+0000] {subprocess.py:93} INFO -   File "<frozen importlib._bootstrap>", line 991, in _find_and_load
[2025-11-01T14:26:34.598+0000] {subprocess.py:93} INFO -   File "<frozen importlib._bootstrap>", line 975, in _find_and_load_unlocked
[2025-11-01T14:26:34.598+0000] {subprocess.py:93} INFO -   File "<frozen importlib._bootstrap>", line 671, in _load_unlocked
[2025-11-01T14:26:34.599+0000] {subprocess.py:93} INFO -   File "<frozen importlib._bootstrap_external>", line 843, in exec_module
[2025-11-01T14:26:34.599+0000] {subprocess.py:93} INFO -   File "<frozen importlib._bootstrap>", line 219, in _call_with_frames_removed
[2025-11-01T14:26:34.599+0000] {subprocess.py:93} INFO -   File "/home/***/.local/lib/python3.8/site-packages/dbt/adapters/clickhouse/__init__.py", line 4, in <module>
[2025-11-01T14:26:34.600+0000] {subprocess.py:93} INFO -     from dbt.adapters.clickhouse.connections import ClickHouseConnectionManager  # noqa
[2025-11-01T14:26:34.600+0000] {subprocess.py:93} INFO -   File "/home/***/.local/lib/python3.8/site-packages/dbt/adapters/clickhouse/connections.py", line 10, in <module>
[2025-11-01T14:26:34.601+0000] {subprocess.py:93} INFO -     from dbt.adapters.clickhouse.dbclient import ChRetryableException, get_db_client
[2025-11-01T14:26:34.601+0000] {subprocess.py:93} INFO -   File "/home/***/.local/lib/python3.8/site-packages/dbt/adapters/clickhouse/dbclient.py", line 9, in <module>
[2025-11-01T14:26:34.602+0000] {subprocess.py:93} INFO -     from dbt.adapters.clickhouse.credentials import ClickHouseCredentials
[2025-11-01T14:26:34.602+0000] {subprocess.py:93} INFO -   File "/home/***/.local/lib/python3.8/site-packages/dbt/adapters/clickhouse/credentials.py", line 9, in <module>
[2025-11-01T14:26:34.603+0000] {subprocess.py:93} INFO -     class ClickHouseCredentials(Credentials):
[2025-11-01T14:26:34.603+0000] {subprocess.py:93} INFO -   File "/home/***/.local/lib/python3.8/site-packages/dbt/adapters/clickhouse/credentials.py", line 38, in ClickHouseCredentials
[2025-11-01T14:26:34.604+0000] {subprocess.py:93} INFO -     tcp_keepalive: Union[bool, tuple[int, int, int], list[int]] = False
[2025-11-01T14:26:34.604+0000] {subprocess.py:93} INFO - TypeError: 'type' object is not subscriptable
[2025-11-01T14:26:34.604+0000] {subprocess.py:93} INFO - 
[2025-11-01T14:26:35.692+0000] {subprocess.py:97} INFO - Command exited with return code 2
[2025-11-01T14:26:35.714+0000] {taskinstance.py:2698} ERROR - Task failed with exception
Traceback (most recent call last):
  File "/home/airflow/.local/lib/python3.8/site-packages/airflow/models/taskinstance.py", line 433, in _execute_task
    result = execute_callable(context=context, **execute_callable_kwargs)
  File "/home/airflow/.local/lib/python3.8/site-packages/airflow/operators/bash.py", line 212, in execute
    raise AirflowException(
airflow.exceptions.AirflowException: Bash command failed. The command returned a non-zero exit code 2.
[2025-11-01T14:26:35.719+0000] {taskinstance.py:1138} INFO - Marking task as UP_FOR_RETRY. dag_id=silver_transformation_pipeline, task_id=dbt_test_linktx, execution_date=20251030T000000, start_date=20251101T142632, end_date=20251101T142635
[2025-11-01T14:26:35.739+0000] {standard_task_runner.py:107} ERROR - Failed to execute job 20 for task dbt_test_linktx (Bash command failed. The command returned a non-zero exit code 2.; 649)
[2025-11-01T14:26:35.757+0000] {local_task_job_runner.py:234} INFO - Task exited with return code 1
[2025-11-01T14:26:35.787+0000] {taskinstance.py:3280} INFO - 0 downstream tasks scheduled from follow-on schedule check
