[2025-11-01T11:41:28.610+0000] {taskinstance.py:1956} INFO - Dependencies all met for dep_context=non-requeueable deps ti=<TaskInstance: silver_transformation_pipeline.dbt_run_merchants scheduled__2025-10-31T00:00:00+00:00 [queued]>
[2025-11-01T11:41:28.628+0000] {taskinstance.py:1956} INFO - Dependencies all met for dep_context=requeueable deps ti=<TaskInstance: silver_transformation_pipeline.dbt_run_merchants scheduled__2025-10-31T00:00:00+00:00 [queued]>
[2025-11-01T11:41:28.629+0000] {taskinstance.py:2170} INFO - Starting attempt 1 of 2
[2025-11-01T11:41:28.661+0000] {taskinstance.py:2191} INFO - Executing <Task(BashOperator): dbt_run_merchants> on 2025-10-31 00:00:00+00:00
[2025-11-01T11:41:28.670+0000] {standard_task_runner.py:60} INFO - Started process 682 to run task
[2025-11-01T11:41:28.678+0000] {standard_task_runner.py:87} INFO - Running: ['***', 'tasks', 'run', 'silver_transformation_pipeline', 'dbt_run_merchants', 'scheduled__2025-10-31T00:00:00+00:00', '--job-id', '32', '--raw', '--subdir', 'DAGS_FOLDER/silver_dag.py', '--cfg-path', '/tmp/tmphsui5r11']
[2025-11-01T11:41:28.685+0000] {standard_task_runner.py:88} INFO - Job 32: Subtask dbt_run_merchants
[2025-11-01T11:41:28.821+0000] {task_command.py:423} INFO - Running <TaskInstance: silver_transformation_pipeline.dbt_run_merchants scheduled__2025-10-31T00:00:00+00:00 [running]> on host 6ac9b46937d1
[2025-11-01T11:41:29.051+0000] {taskinstance.py:2480} INFO - Exporting env vars: AIRFLOW_CTX_DAG_OWNER='***' AIRFLOW_CTX_DAG_ID='silver_transformation_pipeline' AIRFLOW_CTX_TASK_ID='dbt_run_merchants' AIRFLOW_CTX_EXECUTION_DATE='2025-10-31T00:00:00+00:00' AIRFLOW_CTX_TRY_NUMBER='1' AIRFLOW_CTX_DAG_RUN_ID='scheduled__2025-10-31T00:00:00+00:00'
[2025-11-01T11:41:29.056+0000] {subprocess.py:63} INFO - Tmp dir root location: /tmp
[2025-11-01T11:41:29.059+0000] {subprocess.py:75} INFO - Running command: ['/usr/bin/bash', '-c', "docker exec -i dbt bash -lc 'cd /dbt && dbt --no-use-colors run --profiles-dir /dbt --select silver_merchants --full-refresh'"]
[2025-11-01T11:41:29.092+0000] {subprocess.py:86} INFO - Output:
[2025-11-01T11:41:32.623+0000] {subprocess.py:93} INFO - 11:41:32  Running with dbt=1.10.13
[2025-11-01T11:41:33.153+0000] {subprocess.py:93} INFO - 11:41:33  Registered adapter: clickhouse=1.9.5
[2025-11-01T11:41:34.114+0000] {subprocess.py:93} INFO - 11:41:34  Found 3 models, 3 sources, 491 macros
[2025-11-01T11:41:34.121+0000] {subprocess.py:93} INFO - 11:41:34
[2025-11-01T11:41:34.124+0000] {subprocess.py:93} INFO - 11:41:34  Concurrency: 4 threads (target='dev')
[2025-11-01T11:41:34.127+0000] {subprocess.py:93} INFO - 11:41:34
[2025-11-01T11:41:34.714+0000] {subprocess.py:93} INFO - 11:41:34  1 of 1 START sql table model `silver`.`silver_merchants` ....................... [RUN]
[2025-11-01T11:41:34.941+0000] {subprocess.py:93} INFO - 11:41:34  1 of 1 ERROR creating sql table model `silver`.`silver_merchants` .............. [ERROR in 0.22s]
[2025-11-01T11:41:34.958+0000] {subprocess.py:93} INFO - 11:41:34
[2025-11-01T11:41:34.960+0000] {subprocess.py:93} INFO - 11:41:34  Finished running 1 table model in 0 hours 0 minutes and 0.83 seconds (0.83s).
[2025-11-01T11:41:35.205+0000] {subprocess.py:93} INFO - 11:41:35
[2025-11-01T11:41:35.208+0000] {subprocess.py:93} INFO - 11:41:35  Completed with 1 error, 0 partial successes, and 0 warnings:
[2025-11-01T11:41:35.210+0000] {subprocess.py:93} INFO - 11:41:35
[2025-11-01T11:41:35.211+0000] {subprocess.py:93} INFO - 11:41:35  Failure in model silver_merchants (models/silver/silver_merchants.sql)
[2025-11-01T11:41:35.213+0000] {subprocess.py:93} INFO - 11:41:35    Compilation Error in model silver_merchants (models/silver/silver_merchants.sql)
[2025-11-01T11:41:35.214+0000] {subprocess.py:93} INFO -   macro 'dbt_macro__clickhouse__create_table_as' takes not more than 2 argument(s)
[2025-11-01T11:41:35.215+0000] {subprocess.py:93} INFO - 
[2025-11-01T11:41:35.216+0000] {subprocess.py:93} INFO -   > in macro create_table_as (macros/relations/table/create.sql)
[2025-11-01T11:41:35.217+0000] {subprocess.py:93} INFO -   > called by macro default__get_create_table_as_sql (macros/relations/table/create.sql)
[2025-11-01T11:41:35.218+0000] {subprocess.py:93} INFO -   > called by macro get_create_table_as_sql (macros/relations/table/create.sql)
[2025-11-01T11:41:35.219+0000] {subprocess.py:93} INFO -   > called by macro statement (macros/etc/statement.sql)
[2025-11-01T11:41:35.220+0000] {subprocess.py:93} INFO -   > called by macro materialization_table_clickhouse (macros/materializations/table.sql)
[2025-11-01T11:41:35.221+0000] {subprocess.py:93} INFO -   > called by model silver_merchants (models/silver/silver_merchants.sql)
[2025-11-01T11:41:35.221+0000] {subprocess.py:93} INFO - 11:41:35
[2025-11-01T11:41:35.222+0000] {subprocess.py:93} INFO - 11:41:35    compiled code at target/compiled/ck_project/models/silver/silver_merchants.sql
[2025-11-01T11:41:35.223+0000] {subprocess.py:93} INFO - 11:41:35
[2025-11-01T11:41:35.223+0000] {subprocess.py:93} INFO - 11:41:35  Done. PASS=0 WARN=0 ERROR=1 SKIP=0 NO-OP=0 TOTAL=1
[2025-11-01T11:41:36.413+0000] {subprocess.py:97} INFO - Command exited with return code 1
[2025-11-01T11:41:36.434+0000] {taskinstance.py:2698} ERROR - Task failed with exception
Traceback (most recent call last):
  File "/home/airflow/.local/lib/python3.8/site-packages/airflow/models/taskinstance.py", line 433, in _execute_task
    result = execute_callable(context=context, **execute_callable_kwargs)
  File "/home/airflow/.local/lib/python3.8/site-packages/airflow/operators/bash.py", line 212, in execute
    raise AirflowException(
airflow.exceptions.AirflowException: Bash command failed. The command returned a non-zero exit code 1.
[2025-11-01T11:41:36.440+0000] {taskinstance.py:1138} INFO - Marking task as UP_FOR_RETRY. dag_id=silver_transformation_pipeline, task_id=dbt_run_merchants, execution_date=20251031T000000, start_date=20251101T114128, end_date=20251101T114136
[2025-11-01T11:41:36.487+0000] {standard_task_runner.py:107} ERROR - Failed to execute job 32 for task dbt_run_merchants (Bash command failed. The command returned a non-zero exit code 1.; 682)
[2025-11-01T11:41:36.546+0000] {local_task_job_runner.py:234} INFO - Task exited with return code 1
[2025-11-01T11:41:36.593+0000] {taskinstance.py:3280} INFO - 0 downstream tasks scheduled from follow-on schedule check
