[2025-10-31T22:00:19.611+0000] {taskinstance.py:1956} INFO - Dependencies all met for dep_context=non-requeueable deps ti=<TaskInstance: ingestion_pipeline.silver_dbt.dbt_deps manual__2025-10-31T22:00:11.870433+00:00 [queued]>
[2025-10-31T22:00:19.624+0000] {taskinstance.py:1956} INFO - Dependencies all met for dep_context=requeueable deps ti=<TaskInstance: ingestion_pipeline.silver_dbt.dbt_deps manual__2025-10-31T22:00:11.870433+00:00 [queued]>
[2025-10-31T22:00:19.625+0000] {taskinstance.py:2170} INFO - Starting attempt 1 of 2
[2025-10-31T22:00:19.640+0000] {taskinstance.py:2191} INFO - Executing <Task(BashOperator): silver_dbt.dbt_deps> on 2025-10-31 22:00:11.870433+00:00
[2025-10-31T22:00:19.647+0000] {standard_task_runner.py:60} INFO - Started process 344 to run task
[2025-10-31T22:00:19.653+0000] {standard_task_runner.py:87} INFO - Running: ['***', 'tasks', 'run', 'ingestion_pipeline', 'silver_dbt.dbt_deps', 'manual__2025-10-31T22:00:11.870433+00:00', '--job-id', '12', '--raw', '--subdir', 'DAGS_FOLDER/ingestion_dag.py', '--cfg-path', '/tmp/tmpo6gdsxbs']
[2025-10-31T22:00:19.656+0000] {standard_task_runner.py:88} INFO - Job 12: Subtask silver_dbt.dbt_deps
[2025-10-31T22:00:19.737+0000] {task_command.py:423} INFO - Running <TaskInstance: ingestion_pipeline.silver_dbt.dbt_deps manual__2025-10-31T22:00:11.870433+00:00 [running]> on host 9dbfb6fb81d8
[2025-10-31T22:00:19.848+0000] {taskinstance.py:2480} INFO - Exporting env vars: AIRFLOW_CTX_DAG_OWNER='***' AIRFLOW_CTX_DAG_ID='ingestion_pipeline' AIRFLOW_CTX_TASK_ID='silver_dbt.dbt_deps' AIRFLOW_CTX_EXECUTION_DATE='2025-10-31T22:00:11.870433+00:00' AIRFLOW_CTX_TRY_NUMBER='1' AIRFLOW_CTX_DAG_RUN_ID='manual__2025-10-31T22:00:11.870433+00:00'
[2025-10-31T22:00:19.850+0000] {subprocess.py:63} INFO - Tmp dir root location: /tmp
[2025-10-31T22:00:19.854+0000] {subprocess.py:75} INFO - Running command: ['/usr/bin/bash', '-c', "docker exec -i dbt bash -lc 'cd /dbt && dbt --no-use-colors deps --profiles-dir /dbt'"]
[2025-10-31T22:00:19.870+0000] {subprocess.py:86} INFO - Output:
[2025-10-31T22:00:22.266+0000] {subprocess.py:93} INFO - 22:00:22  Running with dbt=1.10.13
[2025-10-31T22:00:22.426+0000] {subprocess.py:93} INFO - 22:00:22  Warning: No packages were found in packages.yml
[2025-10-31T22:00:22.432+0000] {subprocess.py:93} INFO - 22:00:22  Encountered an error:
[2025-10-31T22:00:22.433+0000] {subprocess.py:93} INFO - [Errno 2] No such file or directory: 'dbt_packages'
[2025-10-31T22:00:22.436+0000] {subprocess.py:93} INFO - 22:00:22  Traceback (most recent call last):
[2025-10-31T22:00:22.436+0000] {subprocess.py:93} INFO -   File "/usr/local/lib/python3.11/site-packages/dbt/cli/requires.py", line 178, in wrapper
[2025-10-31T22:00:22.437+0000] {subprocess.py:93} INFO -     result, success = func(*args, **kwargs)
[2025-10-31T22:00:22.437+0000] {subprocess.py:93} INFO -                       ^^^^^^^^^^^^^^^^^^^^^
[2025-10-31T22:00:22.437+0000] {subprocess.py:93} INFO -   File "/usr/local/lib/python3.11/site-packages/dbt/cli/requires.py", line 128, in wrapper
[2025-10-31T22:00:22.438+0000] {subprocess.py:93} INFO -     return func(*args, **kwargs)
[2025-10-31T22:00:22.438+0000] {subprocess.py:93} INFO -            ^^^^^^^^^^^^^^^^^^^^^
[2025-10-31T22:00:22.438+0000] {subprocess.py:93} INFO -   File "/usr/local/lib/python3.11/site-packages/dbt/cli/requires.py", line 254, in wrapper
[2025-10-31T22:00:22.439+0000] {subprocess.py:93} INFO -     return func(*args, **kwargs)
[2025-10-31T22:00:22.439+0000] {subprocess.py:93} INFO -            ^^^^^^^^^^^^^^^^^^^^^
[2025-10-31T22:00:22.440+0000] {subprocess.py:93} INFO -   File "/usr/local/lib/python3.11/site-packages/dbt/cli/requires.py", line 303, in wrapper
[2025-10-31T22:00:22.440+0000] {subprocess.py:93} INFO -     return func(*args, **kwargs)
[2025-10-31T22:00:22.440+0000] {subprocess.py:93} INFO -            ^^^^^^^^^^^^^^^^^^^^^
[2025-10-31T22:00:22.441+0000] {subprocess.py:93} INFO -   File "/usr/local/lib/python3.11/site-packages/dbt/cli/main.py", line 461, in deps
[2025-10-31T22:00:22.441+0000] {subprocess.py:93} INFO -     results = task.run()
[2025-10-31T22:00:22.441+0000] {subprocess.py:93} INFO -               ^^^^^^^^^^
[2025-10-31T22:00:22.442+0000] {subprocess.py:93} INFO -   File "/usr/local/lib/python3.11/site-packages/dbt/task/deps.py", line 231, in run
[2025-10-31T22:00:22.442+0000] {subprocess.py:93} INFO -     system.rmtree(self.project.packages_install_path)
[2025-10-31T22:00:22.442+0000] {subprocess.py:93} INFO -   File "/usr/local/lib/python3.11/site-packages/dbt_common/clients/system.py", line 723, in rmtree
[2025-10-31T22:00:22.443+0000] {subprocess.py:93} INFO -     return shutil.rmtree(path, onerror=chmod_and_retry)
[2025-10-31T22:00:22.443+0000] {subprocess.py:93} INFO -            ^^^^^^^^^^^^^^^^^^^^^^^^^^^^^^^^^^^^^^^^^^^^
[2025-10-31T22:00:22.444+0000] {subprocess.py:93} INFO -   File "/usr/local/lib/python3.11/shutil.py", line 763, in rmtree
[2025-10-31T22:00:22.445+0000] {subprocess.py:93} INFO -     onerror(os.rmdir, path, sys.exc_info())
[2025-10-31T22:00:22.445+0000] {subprocess.py:93} INFO -   File "/usr/local/lib/python3.11/shutil.py", line 761, in rmtree
[2025-10-31T22:00:22.445+0000] {subprocess.py:93} INFO -     os.rmdir(path, dir_fd=dir_fd)
[2025-10-31T22:00:22.446+0000] {subprocess.py:93} INFO - FileNotFoundError: [Errno 2] No such file or directory: 'dbt_packages'
[2025-10-31T22:00:22.446+0000] {subprocess.py:93} INFO - 
[2025-10-31T22:00:23.428+0000] {subprocess.py:97} INFO - Command exited with return code 2
[2025-10-31T22:00:23.443+0000] {taskinstance.py:2698} ERROR - Task failed with exception
Traceback (most recent call last):
  File "/home/airflow/.local/lib/python3.8/site-packages/airflow/models/taskinstance.py", line 433, in _execute_task
    result = execute_callable(context=context, **execute_callable_kwargs)
  File "/home/airflow/.local/lib/python3.8/site-packages/airflow/operators/bash.py", line 212, in execute
    raise AirflowException(
airflow.exceptions.AirflowException: Bash command failed. The command returned a non-zero exit code 2.
[2025-10-31T22:00:23.447+0000] {taskinstance.py:1138} INFO - Marking task as UP_FOR_RETRY. dag_id=ingestion_pipeline, task_id=silver_dbt.dbt_deps, execution_date=20251031T220011, start_date=20251031T220019, end_date=20251031T220023
[2025-10-31T22:00:23.466+0000] {standard_task_runner.py:107} ERROR - Failed to execute job 12 for task silver_dbt.dbt_deps (Bash command failed. The command returned a non-zero exit code 2.; 344)
[2025-10-31T22:00:23.482+0000] {local_task_job_runner.py:234} INFO - Task exited with return code 1
[2025-10-31T22:00:23.512+0000] {taskinstance.py:3280} INFO - 0 downstream tasks scheduled from follow-on schedule check
